
testing roberta-large
Some weights of the model checkpoint at roberta-large were not used when initializing RobertaForMultipleChoice: ['lm_head.dense.bias', 'lm_head.decoder.weight', 'lm_head.layer_norm.weight', 'lm_head.bias', 'lm_head.layer_norm.bias', 'lm_head.dense.weight']
- This IS expected if you are initializing RobertaForMultipleChoice from the checkpoint of a model trained on another task or with another architecture (e.g. initializing a BertForSequenceClassification model from a BertForPreTraining model).
- This IS NOT expected if you are initializing RobertaForMultipleChoice from the checkpoint of a model that you expect to be exactly identical (initializing a BertForSequenceClassification model from a BertForSequenceClassification model).
Some weights of RobertaForMultipleChoice were not initialized from the model checkpoint at roberta-large and are newly initialized: ['classifier.weight', 'classifier.bias']
You should probably TRAIN this model on a down-stream task to be able to use it for predictions and inference.
100%|█████████████████████████████████████████████████████████████████████████████████████████████████████████████████████████████████████████████████████████████████████████████████| 39/39 [00:36<00:00,  1.06it/s]
Traceback (most recent call last):
  File "/users5/znchen/distil/predict_frame.py", line 155, in <module>
    main()
  File "/users5/znchen/distil/predict_frame.py", line 149, in main
    test(args.test_data,args.model_name,args.batch_size)
  File "/users5/znchen/distil/predict_frame.py", line 118, in test
    test_accuracy = accuracy_score(test_labels, preds)
  File "//users5/znchen/anaconda3/envs/q2k/lib/python3.10/site-packages/sklearn/metrics/_classification.py", line 211, in accuracy_score
    y_type, y_true, y_pred = _check_targets(y_true, y_pred)
  File "//users5/znchen/anaconda3/envs/q2k/lib/python3.10/site-packages/sklearn/metrics/_classification.py", line 84, in _check_targets
    check_consistent_length(y_true, y_pred)
  File "//users5/znchen/anaconda3/envs/q2k/lib/python3.10/site-packages/sklearn/utils/validation.py", line 332, in check_consistent_length
    raise ValueError(
ValueError: Found input variables with inconsistent numbers of samples: [1221, 5]